Workbook

Sheet 📊 Параметры
A1: 🚀 ФИНАНСОВАЯ МОДЕЛЬ — Семейное сторителлинг-приложение | B2C
A2: ⚠ Жёлтые ячейки — вводные данные (редактируйте). Синие — расчётные (не трогайте).
A4: 💰 ТАРИФНЫЕ ПЛАНЫ | G4: 📈 РОСТ И КОНВЕРСИЯ
A5: Параметр | B5: Free | C5: Премиум | D5: Семейный | E5: Примечание | G5: Параметр | H5: Значение | I5: Ед.
A6: Цена, руб/мес | B6: 0 | C6: 499 | D6: 799 | E6: Месячная подписка | G6: Установки в М1 (план) | H6: 500 | I6: шт
A7: Цена, руб/год | B7: 0 | C7: 3990 | D7: 6390 | E7: Годовая (-33 %) | G7: Рост установок в мес (%) | H7: 0.15 | I7: %
A8: Историй в месяц | B8: 3 | C8: 9999 | D8: 9999 | E8: 9999 = безлимит | G8: Install → Регистрация | H8: 0.6 | I8: %
A9: Профилей детей | B9: 1 | C9: 1 | D9: 5 | E9: Одновременных | G9: Регистрация → Free-активация | H9: 0.85 | I9: %
A10: Иллюстрации | B10: Нет | C10: Да | D10: Да | G10: Free → Премиум (conv %) | H10: 0.06 | I10: %
A11: PDF-книги | B11: Нет | C11: Да | D11: Да | G11: Free → Семейный (conv %) | H11: 0.02 | I11: %
A12: Обработка личных фото | B12: Нет | C12: Нет | D12: Да | E12: Только Семейный | G12: Премиум → Семейный (upgrade %) | H12: 0.1 | I12: %
A13: Голосовая озвучка | B13: Нет | C13: Нет | D13: Да* | E13: *В разработке | G13: Churn Премиум (мес %) | H13: 0.05 | I13: %
G14: Churn Семейный (мес %) | H14: 0.03 | I14: %
G15: Доля годовых подписок | H15: 0.3 | I15: %
A18: 🤖 ПЕРЕМЕННАЯ СЕБЕСТОИМОСТЬ AI (на пользователя/мес)
A19: Операция | B19: Цена (USD) | C19: Кол-во/мес | D19: Итого USD | E19: Итого RUB
A20: Генерация истории (LLM Groq) | B20: 0.005 | C20: 15 | D20: =B20*C20 | E20: =D20*B26
A21: Иллюстрация AI (Pollinations) | B21: 0.04 | C21: 5 | D21: =B21*C21 | E21: =D21*B26
A22: Обработка фото AI | B22: 0.08 | C22: 3 | D22: =B22*C22 | E22: =D22*B26
A23: Голосовая озвучка TTS | B23: 0.015 | C23: 8 | D23: =B23*C23 | E23: =D23*B26
A24: Storage / CDN на польз. | B24: 0.02 | C24: 1 | D24: =B24*C24 | E24: =D24*B26
A25: ИТОГО AI / польз. / мес (USD) | D25: =SUM(D20:D24) | E25: =D25*B26
A26: Курс USD / RUB | B26: 95 | C26: AI себест. / польз. / мес (RUB) | D26: =D25*B26

Sheet 🔽 Воронка продаж
A1: ВОРОНКА ПРОДАЖ — КАНАЛЫ ПРИВЛЕЧЕНИЯ
A3: 📡 ПАРАМЕТРЫ КАНАЛОВ (редактируемые)
A4: Канал | B4: Бюджет руб/мес | C4: CPM руб | D4: CTR / CPC | E4: CR Install% | F4: Охват/клики | G4: Установки/мес | H4: CPI руб | I4: Примечание
A5: Instagram (таргет) | B5: 50000 | C5: 600 | D5: 0.015 | E5: 0.025 | F5: =ROUND(B5/C5*1000,0) | G5: =ROUND(F5*D5*E5,0) | H5: =IFERROR(B5/G5,0) | I5: CPM-модель
A6: Telegram (посевы) | B6: 30000 | C6: 300 | D6: 0.025 | E6: 0.035 | F6: =ROUND(B6/C6*1000,0) | G6: =ROUND(F6*D6*E6,0) | H6: =IFERROR(B6/G6,0) | I6: CPM-модель
A7: ВКонтакте (таргет) | B7: 20000 | C7: 400 | D7: 0.012 | E7: 0.02 | F7: =ROUND(B7/C7*1000,0) | G7: =ROUND(F7*D7*E7,0) | H7: =IFERROR(B7/G7,0) | I7: CPM-модель
A8: Яндекс.Директ | B8: 15000 | C8: CPC | D8: 15 | E8: 0.04 | F8: =ROUND(B8/D8,0) | G8: =ROUND(F8*E8,0) | H8: =IFERROR(B8/G8,0) | I8: CPC-модель
A9: Инфлюенс-маркетинг | B9: 40000 | C9: CPI | D9: 17 | E9: — | F9: — | G9: =ROUND(IFERROR(B9/D9,0),0) | H9: =D9 | I9: CPI≈17₽/устан. Блогеры: мамы, семья
A10: Офлайн (плакаты/листовки) | B10: 25000 | C10: CPI | D10: 100 | E10: — | F10: — | G10: =ROUND(IFERROR(B10/D10,0),0) | H10: =D10 | I10: CPI≈100₽. Сады, школы, педиатрия
A11: Органика / реферал | B11: 0 | F11: — | G11: =ROUND((G5+G6+G7+G8+G9+G10)*0.20,0) | H11: — | I11: 20% от платных
A12: ИТОГО / мес | B12: =SUM(B5:B11) | G12: =SUM(G5:G11)
A13: CAC (стоимость 1 установки, руб) | B13: =IFERROR(B12/G12,0)
A16: 🌊 ВОРОНКА КОНВЕРСИИ (Месяц 1)
A17: Этап | B17: Кол-во | C17: Конверсия | D17: Потеря | E17: Стоимость этапа (руб) | F17: Комментарий
A18: 1. Установки | B18: =G12 | C18: — | D18: — | E18: =B12 | F18: Все каналы
A19: 2. Регистрации | B19: =ROUND(B18*'📊 Параметры'!H8,0) | C19: ='📊 Параметры'!H8 | D19: =B18-B19 | E19: — | F19: Install→Reg
A20: 3. Free-активные | B20: =ROUND(B19*'📊 Параметры'!H9,0) | C20: ='📊 Параметры'!H9 | D20: =B19-B20 | E20: — | F20: Reg→Activation
A21: 4. Новые Премиум | B21: =ROUND(B20*'📊 Параметры'!H10,0) | C21: ='📊 Параметры'!H10 | D21: =B20-B21 | E21: — | F21: Free→Prem
A22: 5. Новые Семейный | B22: =ROUND(B20*'📊 Параметры'!H11,0) | C22: ='📊 Параметры'!H11 | D22: — | E22: — | F22: Free→Fam
A23: 6. Апгрейд Prem→Fam | B23: =ROUND(B21*'📊 Параметры'!H12,0) | C23: ='📊 Параметры'!H12 | D23: — | E23: — | F23: Upgrade

Sheet 💸 Расходы
A1: СТРУКТУРА РАСХОДОВ — ЕЖЕМЕСЯЧНЫЕ ЗАТРАТЫ
A3: 👥 КОМАНДА (ФОТ с налогами — коэффициент 1.35)
A4: Роль | B4: Оклад руб/мес | C4: Кол-во | D4: С налогами (×1.35) | E4: Примечание
A5: CEO / Product Manager | B5: 130000 | C5: 1 | D5: =B5*C5*1.35 | E5: Продукт, стратегия
A6: Lead Backend Developer | B6: 160000 | C6: 1 | D6: =B6*C6*1.35 | E6: Node.js, Supabase
A7: Frontend Developer | B7: 130000 | C7: 1 | D7: =B7*C7*1.35 | E7: React, Vite
A8: UI/UX Designer | B8: 100000 | C8: 1 | D8: =B8*C8*1.35 | E8: Figma, иллюстрации
A9: Маркетолог / SMM | B9: 90000 | C9: 1 | D9: =B9*C9*1.35 | E9: Instagram, Telegram
A10: DevOps (part-time) | B10: 60000 | C10: 1 | D10: =B10*C10*1.35 | E10: Render.com, CI/CD
A11: Контент-менеджер | B11: 70000 | C11: 1 | D11: =B11*C11*1.35 | E11: Тексты, коммьюнити
A12: ИТОГО ФОТ (с налогами) | D12: =SUM(D5:D11)
A14: 🖥️ ИНФРАСТРУКТУРА И ИНСТРУМЕНТЫ
A15: Сервис | B15: USD/мес | C15: Курс | D15: RUB/мес | E15: Назначение
A16: Render.com (Backend + Frontend) | B16: 50 | C16: ='📊 Параметры'!B26 | D16: =B16*C16 | E16: Хостинг
A17: Supabase Pro | B17: 25 | C17: ='📊 Параметры'!B26 | D17: =B17*C17 | E17: БД + Auth + Storage
A18: Groq API (LLM истории) | B18: 30 | C18: ='📊 Параметры'!B26 | D18: =B18*C18 | E18: Генерация историй
A19: Pollinations / AI Images | B19: 20 | C19: ='📊 Параметры'!B26 | D19: =B19*C19 | E19: Иллюстрации
A20: Resend (Email транзакц.) | B20: 10 | C20: ='📊 Параметры'!B26 | D20: =B20*C20 | E20: Сброс пароля, нотиф.
A21: Cloudflare CDN | B21: 10 | C21: ='📊 Параметры'!B26 | D21: =B21*C21 | E21: CDN + DDoS
A22: Sentry (мониторинг ошибок) | B22: 15 | C22: ='📊 Параметры'!B26 | D22: =B22*C22 | E22: Error tracking
A23: GitHub + CI/CD Actions | B23: 10 | C23: ='📊 Параметры'!B26 | D23: =B23*C23 | E23: Репозиторий
A24: Figma Team | B24: 15 | C24: ='📊 Параметры'!B26 | D24: =B24*C24 | E24: Дизайн
A25: Notion / Linear | B25: 10 | C25: ='📊 Параметры'!B26 | D25: =B25*C25 | E25: Управление проектом
A26: Apple Developer ($99/год) | B26: 9 | C26: ='📊 Параметры'!B26 | D26: =B26*C26 | E26: $99/12 ≈ $9/мес
A27: Google Play ($25 one-time) | B27: 2 | C27: ='📊 Параметры'!B26 | D27: =B27*C27 | E27: Амортизация
A28: Прочие SaaS / аналитика | B28: 20 | C28: ='📊 Параметры'!B26 | D28: =B28*C28 | E28: Amplitude, Hotjar
A29: ИТОГО Инфраструктура | D29: =SUM(D16:D28)
A31: 📋 АДМИНИСТРАТИВНЫЕ И ЮРИДИЧЕСКИЕ РАСХОДЫ
A32: Статья | B32: RUB/мес | E32: Примечание
A33: ИП/ООО — аутсорс-бухгалтерия | B33: 10000 | E33: Ежемесячно
A34: Юридические услуги | B34: 5000 | E34: Договоры, оферта
A35: Банковское обслуживание + эквайринг | B35: 3000 | E35: Комиссии
A36: Офис / коворкинг | B36: 15000 | E36: Рабочее пространство
A37: Корпоративная связь | B37: 3000 | E37: Телефония, интернет
A38: Прочие адм. расходы | B38: 5000 | E38: Командировки, канцелярия
A39: ИТОГО Административные | B39: =SUM(B33:B38)
A41: 📌 ИТОГО ПОСТОЯННЫЕ РАСХОДЫ (без маркетинга и AI) | D41: =D12+D29+B39

Sheet 📈 P&L 24 месяца
A1: ОТЧЁТ О ПРИБЫЛЯХ И УБЫТКАХ — 24 МЕСЯЦА
A2: Показатель | B2: М1 | C2: М2 | D2: М3 | E2: М4 | F2: М5 | G2: М6 | H2: М7 | I2: М8 | J2: М9 | K2: М10 | L2: М11 | M2: М12 | N2: М13 | O2: М14 | P2: М15 | Q2: М16 | R2: М17 | S2: М18 | T2: М19 | U2: М20 | V2: М21 | W2: М22 | X2: М23 | Y2: М24
A3: 👥 ПОЛЬЗОВАТЕЛИ
A4: Новые установки | B4: ='📊 Параметры'!H6 | C4: =ROUND(B4*(1+'📊 Параметры'!H7),0) | D4: =ROUND(C4*(1+'📊 Параметры'!H7),0) | E4: =ROUND(D4*(1+'📊 Параметры'!H7),0) | F4: =ROUND(E4*(1+'📊 Параметры'!H7),0) | G4: =ROUND(F4*(1+'📊 Параметры'!H7),0) | H4: =ROUND(G4*(1+'📊 Параметры'!H7),0) | I4: =ROUND(H4*(1+'📊 Параметры'!H7),0) | J4: =ROUND(I4*(1+'📊 Параметры'!H7),0) | K4: =ROUND(J4*(1+'📊 Параметры'!H7),0) | L4: =ROUND(K4*(1+'📊 Параметры'!H7),0) | M4: =ROUND(L4*(1+'📊 Параметры'!H7),0) | N4: =ROUND(M4*(1+'📊 Параметры'!H7),0) | O4: =ROUND(N4*(1+'📊 Параметры'!H7),0) | P4: =ROUND(O4*(1+'📊 Параметры'!H7),0) | Q4: =ROUND(P4*(1+'📊 Параметры'!H7),0) | R4: =ROUND(Q4*(1+'📊 Параметры'!H7),0) | S4: =ROUND(R4*(1+'📊 Параметры'!H7),0) | T4: =ROUND(S4*(1+'📊 Параметры'!H7),0) | U4: =ROUND(T4*(1+'📊 Параметры'!H7),0) | V4: =ROUND(U4*(1+'📊 Параметры'!H7),0) | W4: =ROUND(V4*(1+'📊 Параметры'!H7),0) | X4: =ROUND(W4*(1+'📊 Параметры'!H7),0) | Y4: =ROUND(X4*(1+'📊 Параметры'!H7),0)
A5: Новые регистрации | B5: =ROUND(B4*'📊 Параметры'!H8,0) | C5: =ROUND(C4*'📊 Параметры'!H8,0) | D5: =ROUND(D4*'📊 Параметры'!H8,0) | E5: =ROUND(E4*'📊 Параметры'!H8,0) | F5: =ROUND(F4*'📊 Параметры'!H8,0) | G5: =ROUND(G4*'📊 Параметры'!H8,0) | H5: =ROUND(H4*'📊 Параметры'!H8,0) | I5: =ROUND(I4*'📊 Параметры'!H8,0) | J5: =ROUND(J4*'📊 Параметры'!H8,0) | K5: =ROUND(K4*'📊 Параметры'!H8,0) | L5: =ROUND(L4*'📊 Параметры'!H8,0) | M5: =ROUND(M4*'📊 Параметры'!H8,0) | N5: =ROUND(N4*'📊 Параметры'!H8,0) | O5: =ROUND(O4*'📊 Параметры'!H8,0) | P5: =ROUND(P4*'📊 Параметры'!H8,0) | Q5: =ROUND(Q4*'📊 Параметры'!H8,0) | R5: =ROUND(R4*'📊 Параметры'!H8,0) | S5: =ROUND(S4*'📊 Параметры'!H8,0) | T5: =ROUND(T4*'📊 Параметры'!H8,0) | U5: =ROUND(U4*'📊 Параметры'!H8,0) | V5: =ROUND(V4*'📊 Параметры'!H8,0) | W5: =ROUND(W4*'📊 Параметры'!H8,0) | X5: =ROUND(X4*'📊 Параметры'!H8,0) | Y5: =ROUND(Y4*'📊 Параметры'!H8,0)
A6: Новые Free-пользователи | B6: =ROUND(B5*'📊 Параметры'!H9,0) | C6: =ROUND(C5*'📊 Параметры'!H9,0) | D6: =ROUND(D5*'📊 Параметры'!H9,0) | E6: =ROUND(E5*'📊 Параметры'!H9,0) | F6: =ROUND(F5*'📊 Параметры'!H9,0) | G6: =ROUND(G5*'📊 Параметры'!H9,0) | H6: =ROUND(H5*'📊 Параметры'!H9,0) | I6: =ROUND(I5*'📊 Параметры'!H9,0) | J6: =ROUND(J5*'📊 Параметры'!H9,0) | K6: =ROUND(K5*'📊 Параметры'!H9,0) | L6: =ROUND(L5*'📊 Параметры'!H9,0) | M6: =ROUND(M5*'📊 Параметры'!H9,0) | N6: =ROUND(N5*'📊 Параметры'!H9,0) | O6: =ROUND(O5*'📊 Параметры'!H9,0) | P6: =ROUND(P5*'📊 Параметры'!H9,0) | Q6: =ROUND(Q5*'📊 Параметры'!H9,0) | R6: =ROUND(R5*'📊 Параметры'!H9,0) | S6: =ROUND(S5*'📊 Параметры'!H9,0) | T6: =ROUND(T5*'📊 Параметры'!H9,0) | U6: =ROUND(U5*'📊 Параметры'!H9,0) | V6: =ROUND(V5*'📊 Параметры'!H9,0) | W6: =ROUND(W5*'📊 Параметры'!H9,0) | X6: =ROUND(X5*'📊 Параметры'!H9,0) | Y6: =ROUND(Y5*'📊 Параметры'!H9,0)
A7: Новые Премиум (мес) | B7: =ROUND(B6*'📊 Параметры'!H10,0) | C7: =ROUND(C6*'📊 Параметры'!H10,0) | D7: =ROUND(D6*'📊 Параметры'!H10,0) | E7: =ROUND(E6*'📊 Параметры'!H10,0) | F7: =ROUND(F6*'📊 Параметры'!H10,0) | G7: =ROUND(G6*'📊 Параметры'!H10,0) | H7: =ROUND(H6*'📊 Параметры'!H10,0) | I7: =ROUND(I6*'📊 Параметры'!H10,0) | J7: =ROUND(J6*'📊 Параметры'!H10,0) | K7: =ROUND(K6*'📊 Параметры'!H10,0) | L7: =ROUND(L6*'📊 Параметры'!H10,0) | M7: =ROUND(M6*'📊 Параметры'!H10,0) | N7: =ROUND(N6*'📊 Параметры'!H10,0) | O7: =ROUND(O6*'📊 Параметры'!H10,0) | P7: =ROUND(P6*'📊 Параметры'!H10,0) | Q7: =ROUND(Q6*'📊 Параметры'!H10,0) | R7: =ROUND(R6*'📊 Параметры'!H10,0) | S7: =ROUND(S6*'📊 Параметры'!H10,0) | T7: =ROUND(T6*'📊 Параметры'!H10,0) | U7: =ROUND(U6*'📊 Параметры'!H10,0) | V7: =ROUND(V6*'📊 Параметры'!H10,0) | W7: =ROUND(W6*'📊 Параметры'!H10,0) | X7: =ROUND(X6*'📊 Параметры'!H10,0) | Y7: =ROUND(Y6*'📊 Параметры'!H10,0)
A8: Новые Семейный (мес) | B8: =ROUND(B6*'📊 Параметры'!H11,0) | C8: =ROUND(C6*'📊 Параметры'!H11,0) | D8: =ROUND(D6*'📊 Параметры'!H11,0) | E8: =ROUND(E6*'📊 Параметры'!H11,0) | F8: =ROUND(F6*'📊 Параметры'!H11,0) | G8: =ROUND(G6*'📊 Параметры'!H11,0) | H8: =ROUND(H6*'📊 Параметры'!H11,0) | I8: =ROUND(I6*'📊 Параметры'!H11,0) | J8: =ROUND(J6*'📊 Параметры'!H11,0) | K8: =ROUND(K6*'📊 Параметры'!H11,0) | L8: =ROUND(L6*'📊 Параметры'!H11,0) | M8: =ROUND(M6*'📊 Параметры'!H11,0) | N8: =ROUND(N6*'📊 Параметры'!H11,0) | O8: =ROUND(O6*'📊 Параметры'!H11,0) | P8: =ROUND(P6*'📊 Параметры'!H11,0) | Q8: =ROUND(Q6*'📊 Параметры'!H11,0) | R8: =ROUND(R6*'📊 Параметры'!H11,0) | S8: =ROUND(S6*'📊 Параметры'!H11,0) | T8: =ROUND(T6*'📊 Параметры'!H11,0) | U8: =ROUND(U6*'📊 Параметры'!H11,0) | V8: =ROUND(V6*'📊 Параметры'!H11,0) | W8: =ROUND(W6*'📊 Параметры'!H11,0) | X8: =ROUND(X6*'📊 Параметры'!H11,0) | Y8: =ROUND(Y6*'📊 Параметры'!H11,0)
A9: Активные Премиум (база) | B9: =B7 | C9: =ROUND(MAX(0,B9*(1-'📊 Параметры'!H13-'📊 Параметры'!H12)+C7),0) | D9: =ROUND(MAX(0,C9*(1-'📊 Параметры'!H13-'📊 Параметры'!H12)+D7),0) | E9: =ROUND(MAX(0,D9*(1-'📊 Параметры'!H13-'📊 Параметры'!H12)+E7),0) | F9: =ROUND(MAX(0,E9*(1-'📊 Параметры'!H13-'📊 Параметры'!H12)+F7),0) | G9: =ROUND(MAX(0,F9*(1-'📊 Параметры'!H13-'📊 Параметры'!H12)+G7),0) | H9: =ROUND(MAX(0,G9*(1-'📊 Параметры'!H13-'📊 Параметры'!H12)+H7),0) | I9: =ROUND(MAX(0,H9*(1-'📊 Параметры'!H13-'📊 Параметры'!H12)+I7),0) | J9: =ROUND(MAX(0,I9*(1-'📊 Параметры'!H13-'📊 Параметры'!H12)+J7),0) | K9: =ROUND(MAX(0,J9*(1-'📊 Параметры'!H13-'📊 Параметры'!H12)+K7),0) | L9: =ROUND(MAX(0,K9*(1-'📊 Параметры'!H13-'📊 Параметры'!H12)+L7),0) | M9: =ROUND(MAX(0,L9*(1-'📊 Параметры'!H13-'📊 Параметры'!H12)+M7),0) | N9: =ROUND(MAX(0,M9*(1-'📊 Параметры'!H13-'📊 Параметры'!H12)+N7),0) | O9: =ROUND(MAX(0,N9*(1-'📊 Параметры'!H13-'📊 Параметры'!H12)+O7),0) | P9: =ROUND(MAX(0,O9*(1-'📊 Параметры'!H13-'📊 Параметры'!H12)+P7),0) | Q9: =ROUND(MAX(0,P9*(1-'📊 Параметры'!H13-'📊 Параметры'!H12)+Q7),0) | R9: =ROUND(MAX(0,Q9*(1-'📊 Параметры'!H13-'📊 Параметры'!H12)+R7),0) | S9: =ROUND(MAX(0,R9*(1-'📊 Параметры'!H13-'📊 Параметры'!H12)+S7),0) | T9: =ROUND(MAX(0,S9*(1-'📊 Параметры'!H13-'📊 Параметры'!H12)+T7),0) | U9: =ROUND(MAX(0,T9*(1-'📊 Параметры'!H13-'📊 Параметры'!H12)+U7),0) | V9: =ROUND(MAX(0,U9*(1-'📊 Параметры'!H13-'📊 Параметры'!H12)+V7),0) | W9: =ROUND(MAX(0,V9*(1-'📊 Параметры'!H13-'📊 Параметры'!H12)+W7),0) | X9: =ROUND(MAX(0,W9*(1-'📊 Параметры'!H13-'📊 Параметры'!H12)+X7),0) | Y9: =ROUND(MAX(0,X9*(1-'📊 Параметры'!H13-'📊 Параметры'!H12)+Y7),0)
A10: Активные Семейный (база) | B10: =B8 | C10: =ROUND(MAX(0,B10*(1-'📊 Параметры'!H14)+C8+B9*'📊 Параметры'!H12),0) | D10: =ROUND(MAX(0,C10*(1-'📊 Параметры'!H14)+D8+C9*'📊 Параметры'!H12),0) | E10: =ROUND(MAX(0,D10*(1-'📊 Параметры'!H14)+E8+D9*'📊 Параметры'!H12),0) | F10: =ROUND(MAX(0,E10*(1-'📊 Параметры'!H14)+F8+E9*'📊 Параметры'!H12),0) | G10: =ROUND(MAX(0,F10*(1-'📊 Параметры'!H14)+G8+F9*'📊 Параметры'!H12),0) | H10: =ROUND(MAX(0,G10*(1-'📊 Параметры'!H14)+H8+G9*'📊 Параметры'!H12),0) | I10: =ROUND(MAX(0,H10*(1-'📊 Параметры'!H14)+I8+H9*'📊 Параметры'!H12),0) | J10: =ROUND(MAX(0,I10*(1-'📊 Параметры'!H14)+J8+I9*'📊 Параметры'!H12),0) | K10: =ROUND(MAX(0,J10*(1-'📊 Параметры'!H14)+K8+J9*'📊 Параметры'!H12),0) | L10: =ROUND(MAX(0,K10*(1-'📊 Параметры'!H14)+L8+K9*'📊 Параметры'!H12),0) | M10: =ROUND(MAX(0,L10*(1-'📊 Параметры'!H14)+M8+L9*'📊 Параметры'!H12),0) | N10: =ROUND(MAX(0,M10*(1-'📊 Параметры'!H14)+N8+M9*'📊 Параметры'!H12),0) | O10: =ROUND(MAX(0,N10*(1-'📊 Параметры'!H14)+O8+N9*'📊 Параметры'!H12),0) | P10: =ROUND(MAX(0,O10*(1-'📊 Параметры'!H14)+P8+O9*'📊 Параметры'!H12),0) | Q10: =ROUND(MAX(0,P10*(1-'📊 Параметры'!H14)+Q8+P9*'📊 Параметры'!H12),0) | R10: =ROUND(MAX(0,Q10*(1-'📊 Параметры'!H14)+R8+Q9*'📊 Параметры'!H12),0) | S10: =ROUND(MAX(0,R10*(1-'📊 Параметры'!H14)+S8+R9*'📊 Параметры'!H12),0) | T10: =ROUND(MAX(0,S10*(1-'📊 Параметры'!H14)+T8+S9*'📊 Параметры'!H12),0) | U10: =ROUND(MAX(0,T10*(1-'📊 Параметры'!H14)+U8+T9*'📊 Параметры'!H12),0) | V10: =ROUND(MAX(0,U10*(1-'📊 Параметры'!H14)+V8+U9*'📊 Параметры'!H12),0) | W10: =ROUND(MAX(0,V10*(1-'📊 Параметры'!H14)+W8+V9*'📊 Параметры'!H12),0) | X10: =ROUND(MAX(0,W10*(1-'📊 Параметры'!H14)+X8+W9*'📊 Параметры'!H12),0) | Y10: =ROUND(MAX(0,X10*(1-'📊 Параметры'!H14)+Y8+X9*'📊 Параметры'!H12),0)
A11: Всего платящих | B11: =B9+B10 | C11: =C9+C10 | D11: =D9+D10 | E11: =E9+E10 | F11: =F9+F10 | G11: =G9+G10 | H11: =H9+H10 | I11: =I9+I10 | ... Y11: =Y9+Y10
A12: 💰 ВЫРУЧКА
A13: Выручка Премиум (руб) | B13: =ROUND(B9*(1-'📊 Параметры'!H15)*'📊 Параметры'!C6+B9*'📊 Параметры'!H15*'📊 Параметры'!C7/12,0) | C13: =ROUND(C9*(1-'📊 Параметры'!H15)*'📊 Параметры'!C6+C9*'📊 Параметры'!H15*'📊 Параметры'!C7/12,0) | D13: =ROUND(D9*(1-'📊 Параметры'!H15)*'📊 Параметры'!C6+D9*'📊 Параметры'!H15*'📊 Параметры'!C7/12,0) | E13: =ROUND(E9*(1-'📊 Параметры'!H15)*'📊 Параметры'!C6+E9*'📊 Параметры'!H15*'📊 Параметры'!C7/12,0) | F13: =ROUND(F9*(1-'📊 Параметры'!H15)*'📊 Параметры'!C6+F9*'📊 Параметры'!H15*'📊 Параметры'!C7/12,0) | G13: =ROUND(G9*(1-'📊 Параметры'!H15)*'📊 Параметры'!C6+G9*'📊 Параметры'!H15*'📊 Параметры'!C7/12,0) | H13: =ROUND(H9*(1-'📊 Параметры'!H15)*'📊 Параметры'!C6+H9*'📊 Параметры'!H15*'📊 Параметры'!C7/12,0) | I13: =ROUND(I9*(1-'📊 Параметры'!H15)*'📊 Параметры'!C6+I9*'📊 Параметры'!H15*'📊 Параметры'!C7/12,0) | J13: =ROUND(J9*(1-'📊 Параметры'!H15)*'📊 Параметры'!C6+J9*'📊 Параметры'!H15*'📊 Параметры'!C7/12,0) | K13: =ROUND(K9*(1-'📊 Параметры'!H15)*'📊 Параметры'!C6+K9*'📊 Параметры'!H15*'📊 Параметры'!C7/12,0) | L13: =ROUND(L9*(1-'📊 Параметры'!H15)*'📊 Параметры'!C6+L9*'📊 Параметры'!H15*'📊 Параметры'!C7/12,0) | M13: =ROUND(M9*(1-'📊 Параметры'!H15)*'📊 Параметры'!C6+M9*'📊 Параметры'!H15*'📊 Параметры'!C7/12,0) | N13: =ROUND(N9*(1-'📊 Параметры'!H15)*'📊 Параметры'!C6+N9*'📊 Параметры'!H15*'📊 Параметры'!C7/12,0) | O13: =ROUND(O9*(1-'📊 Параметры'!H15)*'📊 Параметры'!C6+O9*'📊 Параметры'!H15*'📊 Параметры'!C7/12,0) | P13: =ROUND(P9*(1-'📊 Параметры'!H15)*'📊 Параметры'!C6+P9*'📊 Параметры'!H15*'📊 Параметры'!C7/12,0) | Q13: =ROUND(Q9*(1-'📊 Параметры'!H15)*'📊 Параметры'!C6+Q9*'📊 Параметры'!H15*'📊 Параметры'!C7/12,0) | R13: =ROUND(R9*(1-'📊 Параметры'!H15)*'📊 Параметры'!C6+R9*'📊 Параметры'!H15*'📊 Параметры'!C7/12,0) | S13: =ROUND(S9*(1-'📊 Параметры'!H15)*'📊 Параметры'!C6+S9*'📊 Параметры'!H15*'📊 Параметры'!C7/12,0) | T13: =ROUND(T9*(1-'📊 Параметры'!H15)*'📊 Параметры'!C6+T9*'📊 Параметры'!H15*'📊 Параметры'!C7/12,0) | U13: =ROUND(U9*(1-'📊 Параметры'!H15)*'📊 Параметры'!C6+U9*'📊 Параметры'!H15*'📊 Параметры'!C7/12,0) | V13: =ROUND(V9*(1-'📊 Параметры'!H15)*'📊 Параметры'!C6+V9*'📊 Параметры'!H15*'📊 Параметры'!C7/12,0) | W13: =ROUND(W9*(1-'📊 Параметры'!H15)*'📊 Параметры'!C6+W9*'📊 Параметры'!H15*'📊 Параметры'!C7/12,0) | X13: =ROUND(X9*(1-'📊 Параметры'!H15)*'📊 Параметры'!C6+X9*'📊 Параметры'!H15*'📊 Параметры'!C7/12,0) | Y13: =ROUND(Y9*(1-'📊 Параметры'!H15)*'📊 Параметры'!C6+Y9*'📊 Параметры'!H15*'📊 Параметры'!C7/12,0)
A14: Выручка Семейный (руб) | B14: =ROUND(B10*(1-'📊 Параметры'!H15)*'📊 Параметры'!D6+B10*'📊 Параметры'!H15*'📊 Параметры'!D7/12,0) | C14: =ROUND(C10*(1-'📊 Параметры'!H15)*'📊 Параметры'!D6+C10*'📊 Параметры'!H15*'📊 Параметры'!D7/12,0) | D14: =ROUND(D10*(1-'📊 Параметры'!H15)*'📊 Параметры'!D6+D10*'📊 Параметры'!H15*'📊 Параметры'!D7/12,0) | E14: =ROUND(E10*(1-'📊 Параметры'!H15)*'📊 Параметры'!D6+E10*'📊 Параметры'!H15*'📊 Параметры'!D7/12,0) | F14: =ROUND(F10*(1-'📊 Параметры'!H15)*'📊 Параметры'!D6+F10*'📊 Параметры'!H15*'📊 Параметры'!D7/12,0) | G14: =ROUND(G10*(1-'📊 Параметры'!H15)*'📊 Параметры'!D6+G10*'📊 Параметры'!H15*'📊 Параметры'!D7/12,0) | H14: =ROUND(H10*(1-'📊 Параметры'!H15)*'📊 Параметры'!D6+H10*'📊 Параметры'!H15*'📊 Параметры'!D7/12,0) | I14: =ROUND(I10*(1-'📊 Параметры'!H15)*'📊 Параметры'!D6+I10*'📊 Параметры'!H15*'📊 Параметры'!D7/12,0) | J14: =ROUND(J10*(1-'📊 Параметры'!H15)*'📊 Параметры'!D6+J10*'📊 Параметры'!H15*'📊 Параметры'!D7/12,0) | K14: =ROUND(K10*(1-'📊 Параметры'!H15)*'📊 Параметры'!D6+K10*'📊 Параметры'!H15*'📊 Параметры'!D7/12,0) | L14: =ROUND(L10*(1-'📊 Параметры'!H15)*'📊 Параметры'!D6+L10*'📊 Параметры'!H15*'📊 Параметры'!D7/12,0) | M14: =ROUND(M10*(1-'📊 Параметры'!H15)*'📊 Параметры'!D6+M10*'📊 Параметры'!H15*'📊 Параметры'!D7/12,0) | N14: =ROUND(N10*(1-'📊 Параметры'!H15)*'📊 Параметры'!D6+N10*'📊 Параметры'!H15*'📊 Параметры'!D7/12,0) | O14: =ROUND(O10*(1-'📊 Параметры'!H15)*'📊 Параметры'!D6+O10*'📊 Параметры'!H15*'📊 Параметры'!D7/12,0) | P14: =ROUND(P10*(1-'📊 Параметры'!H15)*'📊 Параметры'!D6+P10*'📊 Параметры'!H15*'📊 Параметры'!D7/12,0) | Q14: =ROUND(Q10*(1-'📊 Параметры'!H15)*'📊 Параметры'!D6+Q10*'📊 Параметры'!H15*'📊 Параметры'!D7/12,0) | R14: =ROUND(R10*(1-'📊 Параметры'!H15)*'📊 Параметры'!D6+R10*'📊 Параметры'!H15*'📊 Параметры'!D7/12,0) | S14: =ROUND(S10*(1-'📊 Параметры'!H15)*'📊 Параметры'!D6+S10*'📊 Параметры'!H15*'📊 Параметры'!D7/12,0) | T14: =ROUND(T10*(1-'📊 Параметры'!H15)*'📊 Параметры'!D6+T10*'📊 Параметры'!H15*'📊 Параметры'!D7/12,0) | U14: =ROUND(U10*(1-'📊 Параметры'!H15)*'📊 Параметры'!D6+U10*'📊 Параметры'!H15*'📊 Параметры'!D7/12,0) | V14: =ROUND(V10*(1-'📊 Параметры'!H15)*'📊 Параметры'!D6+V10*'📊 Параметры'!H15*'📊 Параметры'!D7/12,0) | W14: =ROUND(W10*(1-'📊 Параметры'!H15)*'📊 Параметры'!D6+W10*'📊 Параметры'!H15*'📊 Параметры'!D7/12,0) | X14: =ROUND(X10*(1-'📊 Параметры'!H15)*'📊 Параметры'!D6+X10*'📊 Параметры'!H15*'📊 Параметры'!D7/12,0) | Y14: =ROUND(Y10*(1-'📊 Параметры'!H15)*'📊 Параметры'!D6+Y10*'📊 Параметры'!H15*'📊 Параметры'!D7/12,0)
A15: MRR — ИТОГО ВЫРУЧКА (руб) | B15: =B13+B14 | C15: =C13+C14 | D15: =D13+D14 | E15: =E13+E14 | F15: =F13+F14 | G15: =G13+G14 | H15: =H13+H14 | I15: =I13+I14 | ... Y15: =Y13+Y14
A16: ⚙️ COGS — ПРЯМЫЕ ПЕРЕМЕННЫЕ РАСХОДЫ
A17: AI-расходы (переменные) | B17: =ROUND(B11*'📊 Параметры'!D26,0) | C17: =ROUND(C11*'📊 Параметры'!D26,0) | D17: =ROUND(D11*'📊 Параметры'!D26,0) | E17: =ROUND(E11*'📊 Параметры'!D26,0) | F17: =ROUND(F11*'📊 Параметры'!D26,0) | G17: =ROUND(G11*'📊 Параметры'!D26,0) | H17: =ROUND(H11*'📊 Параметры'!D26,0) | I17: =ROUND(I11*'📊 Параметры'!D26,0) | J17: =ROUND(J11*'📊 Параметры'!D26,0) | K17: =ROUND(K11*'📊 Параметры'!D26,0) | L17: =ROUND(L11*'📊 Параметры'!D26,0) | M17: =ROUND(M11*'📊 Параметры'!D26,0) | N17: =ROUND(N11*'📊 Параметры'!D26,0) | O17: =ROUND(O11*'📊 Параметры'!D26,0) | P17: =ROUND(P11*'📊 Параметры'!D26,0) | Q17: =ROUND(Q11*'📊 Параметры'!D26,0) | R17: =ROUND(R11*'📊 Параметры'!D26,0) | S17: =ROUND(S11*'📊 Параметры'!D26,0) | T17: =ROUND(T11*'📊 Параметры'!D26,0) | U17: =ROUND(U11*'📊 Параметры'!D26,0) | V17: =ROUND(V11*'📊 Параметры'!D26,0) | W17: =ROUND(W11*'📊 Параметры'!D26,0) | X17: =ROUND(X11*'📊 Параметры'!D26,0) | Y17: =ROUND(Y11*'📊 Параметры'!D26,0)
A18: Комиссия App Store / Google Play (30%) | B18: =ROUND(B15*0.30,0) | C18: =ROUND(C15*0.30,0) | D18: =ROUND(D15*0.30,0) | E18: =ROUND(E15*0.30,0) | F18: =ROUND(F15*0.30,0) | G18: =ROUND(G15*0.30,0) | H18: =ROUND(H15*0.30,0) | I18: =ROUND(I15*0.30,0) | ... Y18: =ROUND(Y15*0.30,0)
A19: Эквайринг / платёжная комиссия (2.5%) | B19: =ROUND(B15*0.025,0) | C19: =ROUND(C15*0.025,0) | D19: =ROUND(D15*0.025,0) | E19: =ROUND(E15*0.025,0) | F19: =ROUND(F15*0.025,0) | G19: =ROUND(G15*0.025,0) | H19: =ROUND(H15*0.025,0) | I19: =ROUND(I15*0.025,0) | ... Y19: =ROUND(Y15*0.025,0)
A20: ИТОГО COGS | B20: =B17+B18+B19 | C20: =C17+C18+C19 | D20: =D17+D18+D19 | E20: =E17+E18+E19 | F20: =F17+F18+F19 | G20: =G17+G18+G19 | H20: =H17+H18+H19 | I20: =I17+I18+I19 | ... Y20: =Y17+Y18+Y19
A21: ВАЛОВАЯ ПРИБЫЛЬ | B21: =B15-B20 | C21: =C15-C20 | D21: =D15-D20 | E21: =E15-E20 | F21: =F15-F20 | G21: =G15-G20 | H21: =H15-H20 | I21: =I15-I20 | ... Y21: =Y15-Y20
A22: Gross Margin % | B22: =IFERROR(B21/B15,0) | C22: =IFERROR(C21/C15,0) | D22: =IFERROR(D21/D15,0) | E22: =IFERROR(E21/E15,0) | F22: =IFERROR(F21/F15,0) | G22: =IFERROR(G21/G15,0) | H22: =IFERROR(H21/H15,0) | I22: =IFERROR(I21/I15,0) | ... Y22: =IFERROR(Y21/Y15,0)
A23: 📊 ОПЕРАЦИОННЫЕ РАСХОДЫ (OpEx)
A24: ФОТ команды (с налогами) | B24: ='💸 Расходы'!D12 | C24: ='💸 Расходы'!D12 | D24: ='💸 Расходы'!D12 | E24: ='💸 Расходы'!D12 | F24: ='💸 Расходы'!D12 | G24: ='💸 Расходы'!D12 | H24: ='💸 Расходы'!D12 | I24: ='💸 Расходы'!D12 | J24: ='💸 Расходы'!D12 | K24: ='💸 Расходы'!D12 | L24: ='💸 Расходы'!D12 | M24: ='💸 Расходы'!D12 | N24: ='💸 Расходы'!D12 | O24: ='💸 Расходы'!D12 | P24: ='💸 Расходы'!D12 | Q24: ='💸 Расходы'!D12 | R24: ='💸 Расходы'!D12 | S24: ='💸 Расходы'!D12 | T24: ='💸 Расходы'!D12 | U24: ='💸 Расходы'!D12 | V24: ='💸 Расходы'!D12 | W24: ='💸 Расходы'!D12 | X24: ='💸 Расходы'!D12 | Y24: ='💸 Расходы'!D12
A25: Инфраструктура (масштабируемая) | B25: =ROUND('💸 Расходы'!D29*(1+B11/2000*0.10),0) | C25: =ROUND('💸 Расходы'!D29*(1+C11/2000*0.10),0) | D25: =ROUND('💸 Расходы'!D29*(1+D11/2000*0.10),0) | E25: =ROUND('💸 Расходы'!D29*(1+E11/2000*0.10),0) | F25: =ROUND('💸 Расходы'!D29*(1+F11/2000*0.10),0) | G25: =ROUND('💸 Расходы'!D29*(1+G11/2000*0.10),0) | H25: =ROUND('💸 Расходы'!D29*(1+H11/2000*0.10),0) | I25: =ROUND('💸 Расходы'!D29*(1+I11/2000*0.10),0) | J25: =ROUND('💸 Расходы'!D29*(1+J11/2000*0.10),0) | K25: =ROUND('💸 Расходы'!D29*(1+K11/2000*0.10),0) | L25: =ROUND('💸 Расходы'!D29*(1+L11/2000*0.10),0) | M25: =ROUND('💸 Расходы'!D29*(1+M11/2000*0.10),0) | N25: =ROUND('💸 Расходы'!D29*(1+N11/2000*0.10),0) | O25: =ROUND('💸 Расходы'!D29*(1+O11/2000*0.10),0) | P25: =ROUND('💸 Расходы'!D29*(1+P11/2000*0.10),0) | Q25: =ROUND('💸 Расходы'!D29*(1+Q11/2000*0.10),0) | R25: =ROUND('💸 Расходы'!D29*(1+R11/2000*0.10),0) | S25: =ROUND('💸 Расходы'!D29*(1+S11/2000*0.10),0) | T25: =ROUND('💸 Расходы'!D29*(1+T11/2000*0.10),0) | U25: =ROUND('💸 Расходы'!D29*(1+U11/2000*0.10),0) | V25: =ROUND('💸 Расходы'!D29*(1+V11/2000*0.10),0) | W25: =ROUND('💸 Расходы'!D29*(1+W11/2000*0.10),0) | X25: =ROUND('💸 Расходы'!D29*(1+X11/2000*0.10),0) | Y25: =ROUND('💸 Расходы'!D29*(1+Y11/2000*0.10),0)
A26: Административные расходы | B26: ='💸 Расходы'!B39 | C26: ='💸 Расходы'!B39 | D26: ='💸 Расходы'!B39 | E26: ='💸 Расходы'!B39 | F26: ='💸 Расходы'!B39 | G26: ='💸 Расходы'!B39 | H26: ='💸 Расходы'!B39 | I26: ='💸 Расходы'!B39 | J26: ='💸 Расходы'!B39 | K26: ='💸 Расходы'!B39 | L26: ='💸 Расходы'!B39 | M26: ='💸 Расходы'!B39 | N26: ='💸 Расходы'!B39 | O26: ='💸 Расходы'!B39 | P26: ='💸 Расходы'!B39 | Q26: ='💸 Расходы'!B39 | R26: ='💸 Расходы'!B39 | S26: ='💸 Расходы'!B39 | T26: ='💸 Расходы'!B39 | U26: ='💸 Расходы'!B39 | V26: ='💸 Расходы'!B39 | W26: ='💸 Расходы'!B39 | X26: ='💸 Расходы'!B39 | Y26: ='💸 Расходы'!B39
A27: Маркетинговый бюджет | B27: ='🔽 Воронка продаж'!B12 | C27: =ROUND('🔽 Воронка продаж'!B12*POWER(1+'📊 Параметры'!H7,1),0) | D27: =ROUND('🔽 Воронка продаж'!B12*POWER(1+'📊 Параметры'!H7,2),0) | E27: =ROUND('🔽 Воронка продаж'!B12*POWER(1+'📊 Параметры'!H7,3),0) | F27: =ROUND('🔽 Воронка продаж'!B12*POWER(1+'📊 Параметры'!H7,4),0) | G27: =ROUND('🔽 Воронка продаж'!B12*POWER(1+'📊 Параметры'!H7,5),0) | H27: =ROUND('🔽 Воронка продаж'!B12*POWER(1+'📊 Параметры'!H7,6),0) | I27: =ROUND('🔽 Воронка продаж'!B12*POWER(1+'📊 Параметры'!H7,7),0) | J27: =ROUND('🔽 Воронка продаж'!B12*POWER(1+'📊 Параметры'!H7,8),0) | K27: =ROUND('🔽 Воронка продаж'!B12*POWER(1+'📊 Параметры'!H7,9),0) | L27: =ROUND('🔽 Воронка продаж'!B12*POWER(1+'📊 Параметры'!H7,10),0) | M27: =ROUND('🔽 Воронка продаж'!B12*POWER(1+'📊 Параметры'!H7,11),0) | N27: =ROUND('🔽 Воронка продаж'!B12*POWER(1+'📊 Параметры'!H7,12),0) | O27: =ROUND('🔽 Воронка продаж'!B12*POWER(1+'📊 Параметры'!H7,13),0) | P27: =ROUND('🔽 Воронка продаж'!B12*POWER(1+'📊 Параметры'!H7,14),0) | Q27: =ROUND('🔽 Воронка продаж'!B12*POWER(1+'📊 Параметры'!H7,15),0) | R27: =ROUND('🔽 Воронка продаж'!B12*POWER(1+'📊 Параметры'!H7,16),0) | S27: =ROUND('🔽 Воронка продаж'!B12*POWER(1+'📊 Параметры'!H7,17),0) | T27: =ROUND('🔽 Воронка продаж'!B12*POWER(1+'📊 Параметры'!H7,18),0) | U27: =ROUND('🔽 Воронка продаж'!B12*POWER(1+'📊 Параметры'!H7,19),0) | V27: =ROUND('🔽 Воронка продаж'!B12*POWER(1+'📊 Параметры'!H7,20),0) | W27: =ROUND('🔽 Воронка продаж'!B12*POWER(1+'📊 Параметры'!H7,21),0) | X27: =ROUND('🔽 Воронка продаж'!B12*POWER(1+'📊 Параметры'!H7,22),0) | Y27: =ROUND('🔽 Воронка продаж'!B12*POWER(1+'📊 Параметры'!H7,23),0)
A28: ИТОГО OpEx | B28: =B24+B25+B26+B27 | C28: =C24+C25+C26+C27 | D28: =D24+D25+D26+D27 | E28: =E24+E25+E26+E27 | F28: =F24+F25+F26+F27 | G28: =G24+G25+G26+G27 | H28: =H24+H25+H26+H27 | I28: =I24+I25+I26+I27 | ... Y28: =Y24+Y25+Y26+Y27
A29: EBITDA | B29: =B21-B28 | C29: =C21-C28 | D29: =D21-D28 | E29: =E21-E28 | F29: =F21-F28 | G29: =G21-G28 | H29: =H21-H28 | I29: =I21-I28 | ... Y29: =Y21-Y28
A30: EBITDA Margin % | B30: =IFERROR(B29/B15,0) | C30: =IFERROR(C29/C15,0) | D30: =IFERROR(D29/D15,0) | E30: =IFERROR(E29/E15,0) | F30: =IFERROR(F29/F15,0) | G30: =IFERROR(G29/G15,0) | H30: =IFERROR(H29/H15,0) | I30: =IFERROR(I29/I15,0) | ... Y30: =IFERROR(Y29/Y15,0)
A31: Накопленный денежный поток (CF) | B31: =B29 | C31: =B31+C29 | D31: =C31+D29 | E31: =D31+E29 | F31: =E31+F29 | G31: =F31+G29 | H31: =G31+H29 | I31: =H31+I29 | J31: =I31+J29 | ... Y31: =X31+Y29

Sheet 🎯 Unit Economics
A1: ЮНИТ-ЭКОНОМИКА — КЛЮЧЕВЫЕ МЕТРИКИ
A3: 💵 ARPU — СРЕДНИЙ ДОХОД НА ПОЛЬЗОВАТЕЛЯ
A4: Метрика | B4: Значение | C4: Формула / Источник | D4: Бенчмарк
A5: ARPU Премиум (ежемес.) | B5: ='📊 Параметры'!C6 | C5: Цена Премиум/мес | D5: 300–600 ₽
A6: ARPU Семейный (ежемес.) | B6: ='📊 Параметры'!D6 | C6: Цена Семейный/мес | D6: 600–1 000 ₽
A7: Blended ARPU (М12) | B7: =IFERROR('📈 P&L 24 месяца'!M15/'📈 P&L 24 месяца'!M11,0) | C7: MRR M12 / Платящих M12 | D7: 450–650 ₽
A9: 🎯 CAC — СТОИМОСТЬ ПРИВЛЕЧЕНИЯ
A10: Маркетинговый бюджет М1 | B10: ='🔽 Воронка продаж'!B12 | C10: Из воронки продаж
A11: Установок М1 | B11: ='🔽 Воронка продаж'!G12 | C11: Из воронки продаж
A12: CAC (стоимость установки) | B12: =IFERROR(B10/B11,0) | C12: Бюджет / Установки | D12: 80–300 ₽
A13: Конверсия Install → Paying | B13: ='📊 Параметры'!H10+'📊 Параметры'!H11 | C13: Free→Prem + Free→Fam | D13: 5–12%
A14: CAC на платящего пользователя | B14: =IFERROR(B12/B13,0) | C14: CAC / Conv rate | D14: 700–3 000 ₽
A16: 📊 LTV — LIFETIME VALUE
A17: Avg ARPU (blended) | B17: =B7 | C17: Blended ARPU
A18: Avg Churn (blended, мес %) | B18: =('📊 Параметры'!H13+'📊 Параметры'!H14)/2 | C18: Среднее Prem/Fam | D18: <5%
A19: Avg Lifetime (мес) | B19: =IFERROR(1/B18,0) | C19: 1 / Churn | D19: 12–30 мес
A20: Gross Margin (М12) | B20: ='📈 P&L 24 месяца'!M22 | C20: Gross Margin на М12 | D20: >50%
A21: LTV = ARPU × Lifetime × GM | B21: =B17*B19*B20 | C21: Lifetime Value
A22: LTV / CAC ★ | B22: =IFERROR(B21/B14,0) | C22: Ключевой показатель | D22: >3 — хорошо, >5 — отлично
A23: Payback Period (мес) ★ | B23: =IFERROR(B14/(B17*B20),0) | C23: CAC / (ARPU × GM) | D23: <12 мес
A25: 💲 СЕБЕСТОИМОСТЬ ПАКЕТА НА 1 ПОЛЬЗОВАТЕЛЯ В МЕСЯЦ
A26: Статья затрат | B26: Free | C26: Премиум | D26: Семейный | E26: Расчёт
A27: Генерация историй (LLM) | B27: =0.005*3*'📊 Параметры'!B26 | C27: =0.005*15*'📊 Параметры'!B26 | D27: =0.005*20*'📊 Параметры'!B26
A28: Иллюстрации AI | B28: =0 | C28: =0.040*5*'📊 Параметры'!B26 | D28: =0.040*8*'📊 Параметры'!B26
A29: Обработка личных фото AI | B29: =0 | C29: =0 | D29: =0.080*3*'📊 Параметры'!B26
A30: Голосовая озвучка (TTS) | B30: =0 | C30: =0 | D30: =0.015*8*'📊 Параметры'!B26
A31: Storage / CDN | B31: =0.005*'📊 Параметры'!B26 | C31: =0.020*'📊 Параметры'!B26 | D31: =0.040*'📊 Параметры'!B26
A32: Инфраструктура (на польз.) | B32: ='💸 Расходы'!D29/500 | C32: ='💸 Расходы'!D29/500 | D32: ='💸 Расходы'!D29/500
A33: Поддержка (пропорц.) | B33: =0 | C33: =10000/200 | D33: =15000/100
A34: Платёжная комиссия (2.5%) | B34: =0 | C34: ='📊 Параметры'!C6*0.025 | D34: ='📊 Параметры'!D6*0.025
A35: App Store/GP комиссия (30%) | B35: =0 | C35: ='📊 Параметры'!C6*0.30 | D35: ='📊 Параметры'!D6*0.30
A36: ИТОГО СЕБЕСТОИМОСТЬ (руб/польз./мес) | B36: =SUM(B27:B35) | C36: =SUM(C27:C35) | D36: =SUM(D27:D35)
A37: Маржа на пользователя (руб/мес) | B37: =0-B36 | C37: ='📊 Параметры'!C6-C36 | D37: ='📊 Параметры'!D6-D36
A38: Маржинальность (%) | B38: — | C38: =IFERROR(C37/'📊 Параметры'!C6,0) | D38: =IFERROR(D37/'📊 Параметры'!D6,0)
A41: 🧾 СРЕДНИЙ ЧЕК
A42: Ср. чек Премиум, ежемес. | B42: ='📊 Параметры'!C6
A43: Ср. чек Семейный, ежемес. | B43: ='📊 Параметры'!D6
A44: Ср. чек Премиум, годовой | B44: ='📊 Параметры'!C7
A45: Ср. чек Семейный, годовой | B45: ='📊 Параметры'!D7
A46: Blended ср. чек (М12) | B46: =IFERROR('📈 P&L 24 месяца'!M15/('📈 P&L 24 месяца'!M9+'📈 P&L 24 месяца'!M10),0)

Sheet 🏆 KPI Dashboard
A1: KPI DASHBOARD — КЛЮЧЕВЫЕ ПОКАЗАТЕЛИ
A2: Данные приведены на Месяц 12 (эталонный период)
A4: MRR (М12) Месячная выручка | C4: Платящих (М12) | E4: Установок (М12) | G4: EBITDA (М12)
A5: ='📈 P&L 24 месяца'!M15 | C5: ='📈 P&L 24 месяца'!M11 | E5: ='📈 P&L 24 месяца'!M4 | G5: ='📈 P&L 24 месяца'!M29
A6: Цель: 1 000 000 ₽ | C6: Цель: 500+ | E6: Цель: 2 000+ | G6: Цель: > 0 ₽
A9: LTV / CAC ★ | C9: CAC на платящего | E9: Payback Period (мес) | G9: Gross Margin (М12)
A10: ='🎯 Unit Economics'!B22 | C10: ='🎯 Unit Economics'!B14 | E10: ='🎯 Unit Economics'!B23 | G10: ='📈 P&L 24 месяца'!M22
A11: Цель: >3x | C11: Цель: < 2 000 ₽ | E11: Цель: < 12 мес | G11: Цель: > 50%
A14: Blended ARPU (М12) | C14: Конверсия Free→Pay | E14: Avg Churn (мес) | G14: ARR (М12 × 12)
A15: ='🎯 Unit Economics'!B7 | C15: ='📊 Параметры'!H10+'📊 Параметры'!H11 | E15: =('📊 Параметры'!H13+'📊 Параметры'!H14)/2 | G15: ='📈 P&L 24 месяца'!M15*12
A16: Цель: 450+ ₽ | C16: Цель: > 8% | E16: Цель: < 5% | G16: Цель: 12 000 000 ₽
A19: 📊 СВОДНАЯ ТАБЛИЦА ПО МЕСЯЦАМ (М1–М24)
A20: Месяц | B20: Установки | C20: Платящих | D20: MRR (руб) | E20: OpEx (руб) | F20: EBITDA (руб) | G20: EBITDA % | H20: Накопл. CF
A21: М1 | B21: ='📈 P&L 24 месяца'!B4 | C21: ='📈 P&L 24 месяца'!B11 | D21: ='📈 P&L 24 месяца'!B15 | E21: ='📈 P&L 24 месяца'!B28 | F21: ='📈 P&L 24 месяца'!B29 | G21: ='📈 P&L 24 месяца'!B30 | H21: ='📈 P&L 24 месяца'!B31
A22: М2 | B22: ='📈 P&L 24 месяца'!C4 | C22: ='📈 P&L 24 месяца'!C11 | D22: ='📈 P&L 24 месяца'!C15 | E22: ='📈 P&L 24 месяца'!C28 | F22: ='📈 P&L 24 месяца'!C29 | G22: ='📈 P&L 24 месяца'!C30 | H22: ='📈 P&L 24 месяца'!C31
A23: М3 | B23: ='📈 P&L 24 месяца'!D4 | C23: ='📈 P&L 24 месяца'!D11 | D23: ='📈 P&L 24 месяца'!D15 | E23: ='📈 P&L 24 месяца'!D28 | F23: ='📈 P&L 24 месяца'!D29 | G23: ='📈 P&L 24 месяца'!D30 | H23: ='📈 P&L 24 месяца'!D31
A24: М4 | B24: ='📈 P&L 24 месяца'!E4 | C24: ='📈 P&L 24 месяца'!E11 | D24: ='📈 P&L 24 месяца'!E15 | E24: ='📈 P&L 24 месяца'!E28 | F24: ='📈 P&L 24 месяца'!E29 | G24: ='📈 P&L 24 месяца'!E30 | H24: ='📈 P&L 24 месяца'!E31
A25: М5 | B25: ='📈 P&L 24 месяца'!F4 | C25: ='📈 P&L 24 месяца'!F11 | D25: ='📈 P&L 24 месяца'!F15 | E25: ='📈 P&L 24 месяца'!F28 | F25: ='📈 P&L 24 месяца'!F29 | G25: ='📈 P&L 24 месяца'!F30 | H25: ='📈 P&L 24 месяца'!F31
A26: М6 | B26: ='📈 P&L 24 месяца'!G4 | C26: ='📈 P&L 24 месяца'!G11 | D26: ='📈 P&L 24 месяца'!G15 | E26: ='📈 P&L 24 месяца'!G28 | F26: ='📈 P&L 24 месяца'!G29 | G26: ='📈 P&L 24 месяца'!G30 | H26: ='📈 P&L 24 месяца'!G31
A27: М7 | B27: ='📈 P&L 24 месяца'!H4 | C27: ='📈 P&L 24 месяца'!H11 | D27: ='📈 P&L 24 месяца'!H15 | E27: ='📈 P&L 24 месяца'!H28 | F27: ='📈 P&L 24 месяца'!H29 | G27: ='📈 P&L 24 месяца'!H30 | H27: ='📈 P&L 24 месяца'!H31
A28: М8 | B28: ='📈 P&L 24 месяца'!I4 | C28: ='📈 P&L 24 месяца'!I11 | D28: ='📈 P&L 24 месяца'!I15 | E28: ='📈 P&L 24 месяца'!I28 | F28: ='📈 P&L 24 месяца'!I29 | G28: ='📈 P&L 24 месяца'!I30 | H28: ='📈 P&L 24 месяца'!I31
A29: М9 | B29: ='📈 P&L 24 месяца'!J4 | C29: ='📈 P&L 24 месяца'!J11 | D29: ='📈 P&L 24 месяца'!J15 | E29: ='📈 P&L 24 месяца'!J28 | F29: ='📈 P&L 24 месяца'!J29 | G29: ='📈 P&L 24 месяца'!J30 | H29: ='📈 P&L 24 месяца'!J31
A30: М10 | B30: ='📈 P&L 24 месяца'!K4 | C30: ='📈 P&L 24 месяца'!K11 | D30: ='📈 P&L 24 месяца'!K15 | E30: ='📈 P&L 24 месяца'!K28 | F30: ='📈 P&L 24 месяца'!K29 | G30: ='📈 P&L 24 месяца'!K30 | H30: ='📈 P&L 24 месяца'!K31
A31: М11 | B31: ='📈 P&L 24 месяца'!L4 | C31: ='📈 P&L 24 месяца'!L11 | D31: ='📈 P&L 24 месяца'!L15 | E31: ='📈 P&L 24 месяца'!L28 | F31: ='📈 P&L 24 месяца'!L29 | G31: ='📈 P&L 24 месяца'!L30 | H31: ='📈 P&L 24 месяца'!L31
A32: М12 | B32: ='📈 P&L 24 месяца'!M4 | C32: ='📈 P&L 24 месяца'!M11 | D32: ='📈 P&L 24 месяца'!M15 | E32: ='📈 P&L 24 месяца'!M28 | F32: ='📈 P&L 24 месяца'!M29 | G32: ='📈 P&L 24 месяца'!M30 | H32: ='📈 P&L 24 месяца'!M31
A33: М13 | B33: ='📈 P&L 24 месяца'!N4 | C33: ='📈 P&L 24 месяца'!N11 | D33: ='📈 P&L 24 месяца'!N15 | E33: ='📈 P&L 24 месяца'!N28 | F33: ='📈 P&L 24 месяца'!N29 | G33: ='📈 P&L 24 месяца'!N30 | H33: ='📈 P&L 24 месяца'!N31
A34: М14 | B34: ='📈 P&L 24 месяца'!O4 | C34: ='📈 P&L 24 месяца'!O11 | D34: ='📈 P&L 24 месяца'!O15 | E34: ='📈 P&L 24 месяца'!O28 | F34: ='📈 P&L 24 месяца'!O29 | G34: ='📈 P&L 24 месяца'!O30 | H34: ='📈 P&L 24 месяца'!O31
A35: М15 | B35: ='📈 P&L 24 месяца'!P4 | C35: ='📈 P&L 24 месяца'!P11 | D35: ='📈 P&L 24 месяца'!P15 | E35: ='📈 P&L 24 месяца'!P28 | F35: ='📈 P&L 24 месяца'!P29 | G35: ='📈 P&L 24 месяца'!P30 | H35: ='📈 P&L 24 месяца'!P31
A36: М16 | B36: ='📈 P&L 24 месяца'!Q4 | C36: ='📈 P&L 24 месяца'!Q11 | D36: ='📈 P&L 24 месяца'!Q15 | E36: ='📈 P&L 24 месяца'!Q28 | F36: ='📈 P&L 24 месяца'!Q29 | G36: ='📈 P&L 24 месяца'!Q30 | H36: ='📈 P&L 24 месяца'!Q31
A37: М17 | B37: ='📈 P&L 24 месяца'!R4 | C37: ='📈 P&L 24 месяца'!R11 | D37: ='📈 P&L 24 месяца'!R15 | E37: ='📈 P&L 24 месяца'!R28 | F37: ='📈 P&L 24 месяца'!R29 | G37: ='📈 P&L 24 месяца'!R30 | H37: ='📈 P&L 24 месяца'!R31
A38: М18 | B38: ='📈 P&L 24 месяца'!S4 | C38: ='📈 P&L 24 месяца'!S11 | D38: ='📈 P&L 24 месяца'!S15 | E38: ='📈 P&L 24 месяца'!S28 | F38: ='📈 P&L 24 месяца'!S29 | G38: ='📈 P&L 24 месяца'!S30 | H38: ='📈 P&L 24 месяца'!S31
A39: М19 | B39: ='📈 P&L 24 месяца'!T4 | C39: ='📈 P&L 24 месяца'!T11 | D39: ='📈 P&L 24 месяца'!T15 | E39: ='📈 P&L 24 месяца'!T28 | F39: ='📈 P&L 24 месяца'!T29 | G39: ='📈 P&L 24 месяца'!T30 | H39: ='📈 P&L 24 месяца'!T31
A40: М20 | B40: ='📈 P&L 24 месяца'!U4 | C40: ='📈 P&L 24 месяца'!U11 | D40: ='📈 P&L 24 месяца'!U15 | E40: ='📈 P&L 24 месяца'!U28 | F40: ='📈 P&L 24 месяца'!U29 | G40: ='📈 P&L 24 месяца'!U30 | H40: ='📈 P&L 24 месяца'!U31
A41: М21 | B41: ='📈 P&L 24 месяца'!V4 | C41: ='📈 P&L 24 месяца'!V11 | D41: ='📈 P&L 24 месяца'!V15 | E41: ='📈 P&L 24 месяца'!V28 | F41: ='📈 P&L 24 месяца'!V29 | G41: ='📈 P&L 24 месяца'!V30 | H41: ='📈 P&L 24 месяца'!V31
A42: М22 | B42: ='📈 P&L 24 месяца'!W4 | C42: ='📈 P&L 24 месяца'!W11 | D42: ='📈 P&L 24 месяца'!W15 | E42: ='📈 P&L 24 месяца'!W28 | F42: ='📈 P&L 24 месяца'!W29 | G42: ='📈 P&L 24 месяца'!W30 | H42: ='📈 P&L 24 месяца'!W31
A43: М23 | B43: ='📈 P&L 24 месяца'!X4 | C43: ='📈 P&L 24 месяца'!X11 | D43: ='📈 P&L 24 месяца'!X15 | E43: ='📈 P&L 24 месяца'!X28 | F43: ='📈 P&L 24 месяца'!X29 | G43: ='📈 P&L 24 месяца'!X30 | H43: ='📈 P&L 24 месяца'!X31
A44: М24 | B44: ='📈 P&L 24 месяца'!Y4 | C44: ='📈 P&L 24 месяца'!Y11 | D44: ='📈 P&L 24 месяца'!Y15 | E44: ='📈 P&L 24 месяца'!Y28 | F44: ='📈 P&L 24 месяца'!Y29 | G44: ='📈 P&L 24 месяца'!Y30 | H44: ='📈 P&L 24 месяца'!Y31

Sheet 🎲 Сценарии
A1: АНАЛИЗ СЦЕНАРИЕВ — ЧУВСТВИТЕЛЬНОСТЬ МОДЕЛИ
A3: Параметр | B3: Пессимист. | C3: Базовый (модель) | D3: Оптимист. | E3: Ед. | F3: Описание
A4: Конверсия Free→Premium (%) | B4: 0.03 | C4: ='📊 Параметры'!H10 | D4: 0.1 | E4: % | F4: Ключевой драйвер выручки
A5: Рост установок/мес (%) | B5: 0.08 | C5: ='📊 Параметры'!H7 | D5: 0.25 | E5: % | F5: Эффект маркетинга
A6: Churn Премиум (%/мес) | B6: 0.08 | C6: ='📊 Параметры'!H13 | D6: 0.03 | E6: % | F6: Качество продукта
A7: ARPU Premium (руб/мес) | B7: 399 | C7: ='📊 Параметры'!C6 | D7: 599 | E7: руб | F7: Ценовая эластичность
A8: CAC (руб/установку) | B8: 250 | C8: ='🔽 Воронка продаж'!B13 | D8: 80 | E8: руб | F8: Эффективность каналов
A9: Доля годовых подписок | B9: 0.15 | C9: ='📊 Параметры'!H15 | D9: 0.45 | E9: % | F9: Дисконт vs cash flow
A10: Органика (% от платных) | B10: 0.1 | C10: 20% | D10: 0.35 | E10: % | F10: Виральность
A11: Маркетинг М1 (руб) | B11: 80000 | C11: ='🔽 Воронка продаж'!B12 | D11: 200000 | E11: руб | F11: Стартовый бюджет
A14: 📊 ОЖИДАЕМЫЕ ИТОГИ ПО СЦЕНАРИЯМ (М12)
A15: Метрика | B15: Пессимист. | C15: Базовый (формула) | D15: Оптимист. | E15: Ед.
A16: MRR к М12 (руб) | B16: 300000 | C16: ='📈 P&L 24 месяца'!M15 | D16: 2500000 | E16: руб
A17: Платящих к М12 | B17: 300 | C17: ='📈 P&L 24 месяца'!M11 | D17: 2500 | E17: польз.
A18: EBITDA М12 (руб) | B18: -300000 | C18: ='📈 P&L 24 месяца'!M29 | D18: 900000 | E18: руб
A19: Break-even (мес) | B19: 20 | C19: ~14–16 | D19: 8 | E19: мес
A20: LTV/CAC | B20: 1.5 | C20: ='🎯 Unit Economics'!B22 | D20: 8 | E20: x
A21: Payback Period (мес) | B21: 22 | C21: ='🎯 Unit Economics'!B23 | D21: 5 | E21: мес
A24: 📝 КЛЮЧЕВЫЕ ДОПУЩЕНИЯ МОДЕЛИ
A25: 1. Стоимость AI — публичные тарифы: Groq $0.005/запрос, Pollinations ~$0.04/изображение
A26: 2. Комиссия App Store / Google Play — 30 % (стандарт; < 1M USD/год можно получить 15 %)
A27: 3. Органика = 20 % от платных установок (сарафанное радио, рефералы)
A28: 4. Churn включает добровольные отписки и неуспешные платежи
A29: 5. ФОТ × 1.35: НДФЛ 13 % + страховые взносы ~22 %
A30: 6. Курс USD/RUB = 95 (изменяемый параметр на листе «Параметры»)
A31: 7. Маркетинговый бюджет масштабируется пропорционально плану роста установок
A32: 8. Модель — органический рост без внешних инвестиций
A33: 9. Break-even при базовом сценарии ожидается на 14–16 месяц
A34: 10. Голосовая озвучка (*) — функция в разработке; стоимость TTS оценочная
A35: 11. Доля платных подписок через веб: избегает 30 % комиссии, учтено частично через «Доля годовых»
A36: 12. Инфраструктурные расходы масштабируются +10 % каждые 2 000 платящих пользователей

Sheet 🏫 B2B Модель
A1: B2B МОДЕЛЬ — ЧАСТНЫЕ САДЫ И ШКОЛЫ
A3: 📋 ТАРИФНЫЕ ПЛАНЫ B2B (редактируемые)
A4: Тариф | B4: Кол-во детей/профилей | C4: Цена руб/мес | D4: Цена руб/год | E4: Скидка год% | F4: Функции | G4: Себест-ть/мес | H4: Маржа/мес | I4: Маржа % | J4: Примечание
A5: Мини-сад | B5: 30 | C5: 4900 | D5: =ROUND(C5*12*(1-E5),0) | E5: 0.2 | F5: До 30 детей, все Premium-функции, без фото | G5: 1200 | H5: =C5-G5 | I5: =IFERROR((C5-G5)/C5,0) | J5: Небольшой частный сад
A6: Стандарт-сад | B6: 60 | C6: 8900 | D6: =ROUND(C6*12*(1-E6),0) | E6: 0.2 | F6: До 60 детей, Premium + обработка фото | G6: 2000 | H6: =C6-G6 | I6: =IFERROR((C6-G6)/C6,0) | J6: Средний сад / развивашка
A7: Школа Базовая | B7: 150 | C7: 14900 | D7: =ROUND(C7*12*(1-E7),0) | E7: 0.15 | F7: До 150 учеников, классы/группы, кабинет учит. | G7: 4000 | H7: =C7-G7 | I7: =IFERROR((C7-G7)/C7,0) | J7: Начальная школа
A8: Школа Расширенная | B8: 300 | C8: 24900 | D8: =ROUND(C8*12*(1-E8),0) | E8: 0.15 | F8: До 300 учен., ВСЕ функции + аналитика | G8: 7000 | H8: =C8-G8 | I8: =IFERROR((C8-G8)/C8,0) | J8: Средняя/крупная школа
A9: Корпоративный | B9: 999 | C9: 49900 | D9: =ROUND(C9*12*(1-E9),0) | E9: 0.1 | F9: Безлимит, white-label, API, SLA | G9: 15000 | H9: =C9-G9 | I9: =IFERROR((C9-G9)/C9,0) | J9: Сеть садов/школ
A12: 📈 ПРОГНОЗ ПРОДАЖ B2B — 24 МЕСЯЦА
A13: Показатель | B13: М1 | C13: М2 | D13: М3 | E13: М4 | F13: М5 | G13: М6 | H13: М7 | I13: М8 | J13: М9 | K13: М10 | L13: М11 | M13: М12 | N13: М18 | O13: М24
A14: Новые клиентов/мес (план) | B14: 0 | C14: 0 | D14: 1 | E14: 1 | F14: 2 | G14: 2 | H14: 3 | I14: 3 | J14: 4 | K14: 4 | L14: 5 | M14: 5 | N14: 7 | O14: 10
A15: Накопл. клиентов | B15: =B14 | C15: =B15+C14 | D15: =C15+D14 | E15: =D15+E14 | F15: =E15+F14 | G15: =F15+G14 | H15: =G15+H14 | I15: =H15+I14 | J15: =I15+J14 | ... O15: =N15+O14
A16: Средний чек B2B (руб/мес) | B16: 12000 | C16: 12000 | D16: 12000 | E16: 12000 | F16: 12000 | G16: 12000 | H16: 12000 | I16: 12000 | J16: 12000 | K16: 12000 | L16: 12000 | M16: 12000 | N16: 12000 | O16: 12000
A17: MRR B2B (руб) | B17: =B15*B16 | C17: =C15*C16 | D17: =D15*D16 | E17: =E15*E16 | F17: =F15*F16 | G17: =G15*G16 | H17: =H15*H16 | I17: =I15*I16 | ... O17: =O15*O16
A18: Годовые контракты (руб) | B18: =ROUND(B17*12*0.3*0.85,0) | C18: =ROUND(C17*12*0.3*0.85,0) | D18: =ROUND(D17*12*0.3*0.85,0) | E18: =ROUND(E17*12*0.3*0.85,0) | F18: =ROUND(F17*12*0.3*0.85,0) | G18: =ROUND(G17*12*0.3*0.85,0) | H18: =ROUND(H17*12*0.3*0.85,0) | I18: =ROUND(I17*12*0.3*0.85,0) | ... O18: =ROUND(O17*12*0.3*0.85,0)
A19: Себест-ть B2B итого (руб) | B19: =B15*4000 | C19: =C15*4000 | D19: =D15*4000 | E19: =E15*4000 | F19: =F15*4000 | G19: =G15*4000 | H19: =H15*4000 | I19: =I15*4000 | ... O19: =O15*4000
A20: Валовая прибыль B2B (руб) | B20: =B17-B19 | C20: =C17-C19 | D20: =D17-D19 | E20: =E17-E19 | F20: =F17-F19 | G20: =G17-G19 | H20: =H17-H19 | I20: =I17-I19 | ... O20: =O17-O19
A21: Маржинальность B2B | B21: =IFERROR(B20/B17,0) | C21: =IFERROR(C20/C17,0) | D21: =IFERROR(D20/D17,0) | E21: =IFERROR(E20/E17,0) | F21: =IFERROR(F20/F17,0) | G21: =IFERROR(G20/G17,0) | H21: =IFERROR(H20/H17,0) | I21: =IFERROR(I20/I17,0) | ... O21: =IFERROR(O20/O17,0)
A24: 💰 UNIT ECONOMICS B2B
A25: Бюджет привлечения B2B / мес (руб) | C25: 80000
A26: Кол-во лидов от продаж/мес | C26: 15
A27: CR лид → клиент (%) | C27: 0.2
A28: CAC B2B (руб) | C28: =IFERROR(C25/(C26*C27),0)
A29: Ср. чек/мес B2B (руб) | C29: 12000
A30: Средний срок контракта (мес) | C30: 18
A31: LTV B2B (руб) | C31: =C29*C30
A32: LTV / CAC B2B | C32: =IFERROR(C31/C28,0)
A33: Payback Period B2B (мес) | C33: =IFERROR(C28/C29,0)
A36: 📡 КАНАЛЫ ПРИВЛЕЧЕНИЯ B2B
A37: Канал | B37: Бюджет руб/мес | C37: Лидов/мес | D37: CR лид→клиент | E37: Клиентов/мес | F37: CAC руб | G37: Комментарий
A38: Прямые продажи (звонки/встречи) | B38: 30000 | C38: 10 | D38: 0.3 | E38: =ROUND(C38*D38,1) | F38: =IFERROR(B38/(C38*D38),0) | G38: Менеджер по B2B-продажам
A39: Офлайн: конференции/выставки | B39: 20000 | C39: 5 | D39: 0.25 | E39: =ROUND(C39*D39,1) | F39: =IFERROR(B39/(C39*D39),0) | G39: EdTech-мероприятия, ярмарки
A40: LinkedIn / деловые соцсети | B40: 10000 | C40: 4 | D40: 0.15 | E40: =ROUND(C40*D40,1) | F40: =IFERROR(B40/(C40*D40),0) | G40: HR и директора учреждений
A41: Email-рассылка директорам | B41: 5000 | C41: 3 | D41: 0.2 | E41: =ROUND(C41*D41,1) | F41: =IFERROR(B41/(C41*D41),0) | G41: База из открытых реестров
A42: Партнёрства (агентства EdTech) | B42: 15000 | C42: 3 | D42: 0.35 | E42: =ROUND(C42*D42,1) | F42: =IFERROR(B42/(C42*D42),0) | G42: Реферальное вознаграждение 10%
A43: ИТОГО B2B | B43: =SUM(B38:B42) | C43: =SUM(C38:C42) | E43: =SUM(E38:E42)
A44: Взвешенный CAC B2B (бюджет / клиентов) | B44: =IFERROR(B43/E43,0)
A47: 📊 СОВОКУПНЫЙ ИТОГ (B2C + B2B) — 12 МЕСЯЦ
A48: MRR B2C (руб) — из листа P&L | C48: ='📈 P&L 24 месяца'!N6
A49: MRR B2B (руб) — текущий лист | C49: =N17
...
